Workbook
Name a: 'Project 2 Staffing Needs'!#REF!
Name a: Staffing!#REF!
Name a: 'Staffing - Baseline'!#REF!
Name a: #REF!
Name aa: 'Project 2 Staffing Needs'!#REF!
Name aa: Staffing!#REF!
Name aa: 'Staffing - Baseline'!#REF!
Name aa: #REF!
Name BPA: 'Project 2 Staffing Needs'!#REF!
Name BPA: Staffing!#REF!
Name BPA: 'Staffing - Baseline'!#REF!
Name BPA: #REF!
Name COMPLEXITY: #REF!
Name DeloitteTeamMembers: 'Project 2 Staffing Needs'!#REF!
Name DeloitteTeamMembers: Staffing!#REF!
Name DeloitteTeamMembers: 'Staffing - Baseline'!#REF!
Name DeloitteTeamMembers: #REF!
Name level: #REF!
Name Manufacturingsites: #REF!
Name MM_Level: 'Project 2 Staffing Needs'!#REF!
Name MM_Level: Staffing!#REF!
Name MM_Level: 'Staffing - Baseline'!#REF!
Name MM_Level: #REF!
Name MM_MD_Level: 'Project 2 Staffing Needs'!#REF!
Name MM_MD_Level: Staffing!#REF!
Name MM_MD_Level: 'Staffing - Baseline'!#REF!
Name MM_MD_Level: #REF!
Name MMNew: 'Project 2 Staffing Needs'!#REF!
Name MMNew: Staffing!#REF!
Name MMNew: 'Staffing - Baseline'!#REF!
Name MMNew: #REF!
Name Projects: 'Project 2 Staffing Needs'!#REF!
Name Projects: Staffing!#REF!
Name Projects: 'Staffing - Baseline'!#REF!
Name Projects: #REF!
Name Rates_b_: #REF!
Name Rates_c_: #REF!
Name Region: #REF!
Name Regions: #REF!
Name reqCat: #REF!
Name reqSubCat: #REF!
Name ReqType: #REF!
Name ResourceCohort_Filtered: _xlfn.ANCHORARRAY(#REF!)
Name STATUS: #REF!
Name Team: 'Project 2 Staffing Needs'!#REF!
Name Team: Staffing!#REF!
Name Team: 'Staffing - Baseline'!#REF!
Name Team: #REF!
Name VP: #REF!

Sheet Timeline - Monthly
E1: 46023 | AN1: 46388 | CN1: 46753
E2: 46148 | I2: 46174 | N2: 46209 | R2: 46237 | W2: 46272 | AA2: 46300 | AE2: 46328 | AJ2: 46363 | AN2: 46391 | AR2: 46419 | AV2: 46447 | BA2: 46482 | BE2: 46510 | BJ2: 46543 | BN2: 46573 | BR2: 46602 | BW2: 46635 | CA2: 46665 | CE2: 46694 | CJ2: 46726 | CN2: 46755 | CS2: 46788 | CW2: 46817 | DA2: 46848 | DE2: 46876 | DJ2: 46909 | DN2: 46937 | DS2: 46970 | DW2: 47001 | EA2: 47029 | EF2: 47062 | EJ2: 47092 | EN2: 47121
E3: =F3-7 -> 46146 | F3: =G3-7 -> 46153 | G3: =H3-7 -> 46160 | H3: =I3-7 -> 46167 | I3: 46174 | J3: =I3+7 -> 46181 | K3: =J3+7 -> 46188 | L3: =K3+7 -> 46195 | M3: =L3+7 -> 46202 | N3: =M3+7 -> 46209 | O3: =N3+7 -> 46216 | P3: =O3+7 -> 46223 | Q3: =P3+7 -> 46230 | ... EW3: =EV3+7 -> 47182
B4: Ending | G4: =G3+4 -> 46164 | H4: =H3+4 -> 46171 | I4: =I3+4 -> 46178 | J4: =J3+4 -> 46185 | K4: =K3+4 -> 46192 | L4: =L3+4 -> 46199 | M4: =M3+4 -> 46206 | N4: =N3+4 -> 46213 | ... CM4: =CM3+4 -> 46752
B5: Week# | G5: 1 | H5: 2 | I5: 3 | J5: 4 | K5: 5 | L5: 6 | M5: 7 | P5: 1 | Q5: =P5+1 -> 2 | R5: =Q5+1 -> 3 | S5: =R5+1 -> 4 | T5: =S5+1 -> 5 | U5: =T5+1 -> 6 | V5: =U5+1 -> 7 | W5: =V5+1 -> 8 | X5: =W5+1 -> 9 | ... CD5: =CC5+1 -> 67
B7: Edison | G7: Edison
N8: ROM for S/4 Enterprise implementation
B10: Global Design | I10: Global Design | Y10: Cross OpCo - Phase 0 | AG10: High Level Scoping, KDDs, Harmonization Opportunities
B13: ABT Implementation | L13: AlphaBio Implementaiton | U13: Prep | W13: 1 | AA13: 2 | AE13: 3 | AI13: 4 | AV13: MC1 | BB13: MC2 | BH13: CS | BP13: FC | BS13: HYC
AJ14: 1 | AP14: 2 | AS14: 3 | AX14: SIT 1 | BD14: SIT 2 | BK14: UAT/OQ/PQ
B21: Assessment Phase
B24: S4 Implementation
R34: Assessment
X37: Prep | Z37: 1 | AF37: 2 | AN37: 3 | AT37: 4 | AZ37: 5 | BX37: MC1 | CG37: MC2 | CR37: CS | DB37: FPC | DF37: HYC
AC38: 1 | AZ38: 1 | BF38: 2 | BL38: 3 | BR38: 4 | CB38: SIT 1 | CK38: SIT 2 | CN38: SIT 2 | CV38: UAT/OQ/PQ

Sheet Timeline
B1: Year | C1: 46023 | AU1: 46388 | CW1: 46753
B2: Month | C2: 46082 | H2: 46118 | L2: 46148 | P2: 46174 | U2: 46209 | Y2: 46237 | AD2: 46272 | AH2: 46300 | AL2: 46328 | AQ2: 46363 | AU2: 46391 | AY2: 46419 | BC2: 46447 | BH2: 46482 | BL2: 46510 | BQ2: 46543 | BU2: 46573 | BZ2: 46602 | CF2: 46635 | CJ2: 46665 | CN2: 46694 | CS2: 46726 | CW2: 46755 | DB2: 46788 | DF2: 46817 | DJ2: 46848 | DN2: 46876 | DS2: 46909 | DW2: 46937 | EB2: 46970 | EF2: 47001 | EJ2: 47029 | EO2: 47062 | ES2: 47092 | EW2: 47121
B3: Week Start | C3: =D3-7 -> 46083 | D3: =E3-7 -> 46090 | E3: =F3-7 -> 46097 | F3: =G3-7 -> 46104 | G3: =H3-7 -> 46111 | H3: =I3-7 -> 46118 | I3: =J3-7 -> 46125 | J3: =K3-7 -> 46132 | ... O3: =P3-7 -> 46167 | P3: 46174 | Q3: =P3+7 -> 46181 | R3: =Q3+7 -> 46188 | S3: =R3+7 -> 46195 | T3: =S3+7 -> 46202 | U3: =T3+7 -> 46209 | V3: =U3+7 -> 46216 | W3: =V3+7 -> 46223 | X3: =W3+7 -> 46230 | ... BU3: =BT3+7 -> 46573 | BW3: =BU3+7 -> 46580 | BX3: =BW3+7 -> 46587 | BY3: =BX3+7 -> 46594 | BZ3: =BY3+7 -> 46601 | CA3: =BZ3+7 -> 46608 | CB3: =CA3+7 -> 46615 | CC3: =CB3+7 -> 46622 | CE3: =CC3+7 -> 46629 | CF3: =CE3+7 -> 46636 | CG3: =CF3+7 -> 46643 | CH3: =CG3+7 -> 46650 | CI3: =CH3+7 -> 46657 | CJ3: =CI3+7 -> 46664 | CK3: =CJ3+7 -> 46671 | CL3: =CK3+7 -> 46678 | CM3: =CL3+7 -> 46685 | ... FF3: =FE3+7 -> 47182
B4: Week End | C4: =C3+4 -> 46087 | D4: =D3+4 -> 46094 | E4: =E3+4 -> 46101 | F4: =F3+4 -> 46108 | G4: =G3+4 -> 46115 | H4: =H3+4 -> 46122 | I4: =I3+4 -> 46129 | J4: =J3+4 -> 46136 | ... BU4: =BU3+4 -> 46577 | BW4: =BW3+4 -> 46584 | BX4: =BX3+4 -> 46591 | BY4: =BY3+4 -> 46598 | BZ4: =BZ3+4 -> 46605 | CA4: =CA3+4 -> 46612 | CB4: =CB3+4 -> 46619 | CC4: =CC3+4 -> 46626 | CE4: =CE3+4 -> 46633 | CF4: =CF3+4 -> 46640 | CG4: =CG3+4 -> 46647 | CH4: =CH3+4 -> 46654 | CI4: =CI3+4 -> 46661 | CJ4: =CJ3+4 -> 46668 | CK4: =CK3+4 -> 46675 | CL4: =CL3+4 -> 46682 | ... FA4: =FA3+4 -> 47151
B5: Week# | N5: 1 | O5: 2 | P5: 3 | Q5: 4 | R5: 5 | S5: 6 | T5: 7 | W5: 1 | X5: =W5+1 -> 2 | Y5: =X5+1 -> 3 | Z5: =Y5+1 -> 4 | AA5: =Z5+1 -> 5 | AB5: =AA5+1 -> 6 | AC5: =AB5+1 -> 7 | AD5: =AC5+1 -> 8 | AE5: =AD5+1 -> 9 | ... BU5: =BT5+1 -> 51 | BW5: =BU5+1 -> 52 | BX5: =BW5+1 -> 53 | BY5: =BX5+1 -> 54 | BZ5: =BY5+1 -> 55 | CA5: =BZ5+1 -> 56 | CB5: =CA5+1 -> 57 | CC5: =CB5+1 -> 58 | CE5: =CC5+1 -> 59 | CF5: =CE5+1 -> 60 | CG5: =CF5+1 -> 61 | CH5: =CG5+1 -> 62 | CI5: =CH5+1 -> 63 | CJ5: =CI5+1 -> 64 | CK5: =CJ5+1 -> 65 | CL5: =CK5+1 -> 66 | CM5: =CL5+1 -> 67
B7: Original
B8: S4 Implementation | L8: Readiness | Y8: 1 | AC8: 2 | AG8: 3 | AK8: 4 | AO8: 5 | AU8: 6 | AY8: 7 | BX8: MC1 | CH8: MC2 | CQ8: MC3 | DB8: CS | DK8: FPC | DO8: HYC
W9: Prep | AB9: 1 | AU9: 1 | AY9: 2 | BC9: 3 | BG9: 4 | BK9: 5 | BO9: 6 | BS9: 7 | CB9: SIT 1 | CL9: SIT 2 | CW9: UAT/Val test | DF9: Dry Run
B10: Go-Live: 21 Months
Y11: Non-Prod Hardware Deployment | BX11: Prod Hardware Deployment
B16: Updated
B17: Assessment Phase | AD17: Assessment
B20: S4 Implementation | AN20: Prep | AP20: 1 | AT20: 2 | AZ20: 3 | BD20: 4 | BH20: 5 | BL20: 6 | BP20: 7 | CP20: MC1 | DA20: MC2 | DJ20: MC3 | DS20: CS | EB20: FPC | EF20: HYC
AS21: 1 | BL21: 1 | BP21: 2 | BT21: 3 | BY21: 4 | CC21: 5 | CH21: 6 | CL21: 7 | CT21: SIT 1 | DE21: SIT 2 | DN21: UAT/Val test | DW21: Dry Run
B22: Go-Live: 21 Months | AP22: Non-Prod Hardware Deployment
AD27: PLAN | AP27: Imagine
BD28: Deliver - Build | CC28: Deliver - Test | DJ28: Run (Deploy / Run)
B29: S4 Implementation | AD29: Scoping and Planning Phase | BD29: Build 1 | BH29: Build 2 | BL29: Build 3 | BP29: Build 4 | BT29: Build 5 | BY29: Build 6 | CG29: SIT 1 | CP29: SIT 2 | DA29: UAT/Val Test | DJ29: Dry Run
AN30: Prep | AP30: Design 1 | AV30: Design 2 | AZ30: Design 3 | BD30: Design 4 | BH30: Design 5 | CA30: MC1 | CK30: MC2 | CX30: MC3 | DG30: CS | DP30: FPC | DS30: HYC
B34: PMO | AP34: Ongoing project execution activities and status reporting | BP34: MC1 Plan | CA34: Mock Cutover 1 | CK34: Mock Cutover 2 | CX34: MC 3 | DG34: Cutover Simulation | DP34: Final Cutover
AN35: Sprint plan | BD35: Test Strategy | BP35: SIT 1 Plan | BY35: SIT 1 Scripts | CG35: SIT 1 Execution | CP35: SIT 2 Execution | DA35: UAT Execution | DJ35: Dry Run Execution | DP35: AMS KT | DS35: Hypercare Support
CM36: SIT 2 Scripts | CX36: UAT/CSV scripts Scripts
AZ38: golden copy
B39: Brownfield/Tech
AL40: Upgrade Prep | AP40: Sandbox Upgrade | AV40: Dev Build | AX40: Dev SPAU | BA40: Dev Code Rem | BL40: SBX Build | BQ40: Pre-Prod Build | BU40: QA Build | CH40: Pre-Prod Build | CR40: QA Build | DC40: Pre-Prod Build | DJ40: Prod Build | DS40: Hypercare Support
B44: Process | AL44: WS Prep | AQ44: Innov. Design WS | AZ44: Fit/Gap | BE44: Configuration, WRICEF Development, Unit Testing | CG44: Execute SIT 1 | CP44: Execute SIT 2 | DA44: Support UAT | DJ44: Support Dry Run | DS44: Support HYP
AX45: SDT Review | BG45: Support SDT & Remediation Activities | BW45: SIT Prep | CB45: Support MC1 | CK45: Support MC2 | CX45: Support MC2 | DG45: Support CS | DP45: Support FC
B49: Data | BC49: SDT Setup | BF49: SDT Blueprint | BJ49: SDT Build | BN49: SDT DDR1 | BR49: Def Fix
AN50: Profiling Tool Setup | AT50: Data Profling build | AX50: Profiling results review & Cleansing plan | BD50: Finalize FI structure
AP51: Data Profilng wkshp | AX51: Fin Data restructuring analysis | BG51: Data Validation Tool Build | BR51: Data Validation Tool execution
CS53: Training translations & LMS uploads
B54: OCM | AD54: OCM Scans | AH54: OCM Project Plans | AP54: Change Impact Analysis | BM54: Training Strategy | BT54: Training curriculum | CE54: Training material development | CX54: Train the Trainer | DF54: End User Training delivery
AF55: Plan for Project Team Training | AM55: Stakeholder Identification & Analysis | BC55: OCM Strategy | CV55: Training delivery planning and logistics
BG56: Comms Strategy & Comms Plan | BP56: Foundational Comms & Adoption Assistant Stand-up | BZ56: Communication and engagement deployment per plan
BZ57: Awareness Campaign | CN57: Understanding Campaign | DB57: Readiness Campaign | DN57: Cutover & Go-Live Campaign
CL58: Change Readiness Survey | DA58: Change Readiness Survey | DM58: Change Readiness Survey
BU59: Change Network Identification & Stand-up | CC59: Change Network Engagement
B61: Analytics | AE61: Data Source Impact | AP61: Fit-to-standard workshops | AW61: Rationalization | BD61: Migrate and re-point data sources | BL61: Extractor Remediation | BT61: New CDS view Developments | CE61: MC1 | CG61: Analytics SIT 1 Support | CN61: MC2 | CP61: Analytics SIT 2 Support | CY61: MC3 | DA61: UAT/Val Test Support | DJ61: Dry Run Support | DS61: Hypercare Support
AE62: Analytics Scope & BDC Decision | AR62: Fit Gap of Data Sources | AY62: FDS for reimagine | BE62: Technical Design | BN62: Data Model Remediation | BT62: New Data Sources | CA62: Test Scripts for SIT | CS62: Test Scripts for UAT
B66: Security | AF66: Cyber Risk Assessment | AQ66: Conduct Security Workshops for Reimagine Processes | BI66: Build and Unit Test Security Design
...

Sheet Sheet1

Sheet Pivot
B4: Sum of Total Fees | C4: Location
B5: Team | C5: India | D5: Mexico | E5: US | F5: Total Result | I5: Current % | J5: Proposed % | K5: Proposed Fee | L5: Reduction Fees | M5: Comments
B6: Analytics | C6: 911250 | E6: 269280 | F6: 1180530 | I6: =GETPIVOTDATA("Total Fees",$B$4,"Team","Analytics")/GETPIVOTDATA("Total Fees",$B$4) -> #REF! | J6: 0.057 | K6: =J6*$F$22 -> 2451000 | L6: =GETPIVOTDATA("Total Fees",$B$4,"Team","Analytics")-K6 -> #REF!
B7: Data | C7: 515340 | E7: 1126080 | F7: 1641420 | I7: =GETPIVOTDATA("Total Fees",$B$4,"Team","Data")/GETPIVOTDATA("Total Fees",$B$4) -> #REF! | J7: 0.03 | K7: =J7*$F$22 -> 1290000 | L7: =GETPIVOTDATA("Total Fees",$B$4,"Team","Data")-K7 -> #REF!
B8: Deployment | C8: 371340 | E8: 685440 | F8: 1056780 | I8: =GETPIVOTDATA("Total Fees",$B$4,"Team","Deployment")/GETPIVOTDATA("Total Fees",$B$4) -> #REF! | J8: 0.03 | K8: =J8*$F$22 -> 1290000 | L8: =GETPIVOTDATA("Total Fees",$B$4,"Team","Deployment")-K8 -> #REF!
B9: OCM | C9: 936896 | D9: 512358 | E9: 3060974 | F9: 4510228 | I9: =GETPIVOTDATA("Total Fees",$B$4,"Team","OCM")/GETPIVOTDATA("Total Fees",$B$4) -> #REF! | J9: 0.1 | K9: =J9*$F$22 -> 4300000 | L9: =GETPIVOTDATA("Total Fees",$B$4,"Team","OCM")-K9 -> #REF!
B10: OTC | C10: 1164420 | E10: 1546830 | F10: 2711250 | I10: =GETPIVOTDATA("Total Fees",$B$4,"Team","OTC")/GETPIVOTDATA("Total Fees",$B$4) -> #REF! | J10: 0.06 | K10: =J10*$F$22 -> 2580000 | L10: =GETPIVOTDATA("Total Fees",$B$4,"Team","OTC")-K10 -> #REF!
B11: PMO | C11: 737936 | E11: 2584144 | F11: 3322080 | I11: =GETPIVOTDATA("Total Fees",$B$4,"Team","PMO")/GETPIVOTDATA("Total Fees",$B$4) -> #REF! | J11: 0.08 | K11: =J11*$F$22 -> 3440000 | L11: =GETPIVOTDATA("Total Fees",$B$4,"Team","PMO")-K11 -> #REF!
B12: PTD | C12: 4541850 | E12: 2202480 | F12: 6744330 | I12: =GETPIVOTDATA("Total Fees",$B$4,"Team","PTD")/GETPIVOTDATA("Total Fees",$B$4) -> #REF! | J12: 0.12 | K12: =J12*$F$22 -> 5160000 | L12: =GETPIVOTDATA("Total Fees",$B$4,"Team","PTD")-K12 -> #REF! | M12: Plan 2%; Mfg 4%; Logistics 6%
B13: PTP | C13: 1416960 | E13: 1101600 | F13: 2518560 | I13: =GETPIVOTDATA("Total Fees",$B$4,"Team","PTP")/GETPIVOTDATA("Total Fees",$B$4) -> #REF! | J13: 0.05 | K13: =J13*$F$22 -> 2150000 | L13: =GETPIVOTDATA("Total Fees",$B$4,"Team","PTP")-K13 -> #REF!
B14: RTR | C14: 2692215 | E14: 1839060 | F14: 4531275 | I14: =GETPIVOTDATA("Total Fees",$B$4,"Team","RTR")/GETPIVOTDATA("Total Fees",$B$4) -> #REF! | J14: 0.1 | K14: =J14*$F$22 -> 4300000 | L14: =GETPIVOTDATA("Total Fees",$B$4,"Team","RTR")-K14 -> #REF!
B15: S&R | C15: 626400 | E15: 889200 | F15: 1515600 | I15: =GETPIVOTDATA("Total Fees",$B$4,"Team","S&R")/GETPIVOTDATA("Total Fees",$B$4) -> #REF! | J15: 0.03 | K15: =J15*$F$22 -> 1290000 | L15: =GETPIVOTDATA("Total Fees",$B$4,"Team","S&R")-K15 -> #REF!
B16: Security | C16: 871750 | E16: 2257035 | F16: 3128785 | I16: =GETPIVOTDATA("Total Fees",$B$4,"Team","Solution Architecture")/GETPIVOTDATA("Total Fees",$B$4) -> #REF! | J16: 0.06 | K16: =J16*$F$22 -> 2580000 | L16: =GETPIVOTDATA("Total Fees",$B$4,"Team","Security")-K16 -> #REF!
B17: Solution Architecture | C17: 277965 | E17: 979488 | F17: 1257453 | I17: =GETPIVOTDATA("Total Fees",$B$4,"Team","Solution Architecture")/GETPIVOTDATA("Total Fees",$B$4) -> #REF! | J17: 0.02 | K17: =J17*$F$22 -> 860000 | L17: =GETPIVOTDATA("Total Fees",$B$4,"Team","Solution Architecture")-K17 -> #REF!
B18: TAX | C18: 2512200 | E18: 1643700 | F18: 4155900 | I18: =GETPIVOTDATA("Total Fees",$B$4,"Team","TAX")/GETPIVOTDATA("Total Fees",$B$4) -> #REF! | J18: 0.08 | K18: =J18*$F$22 -> 3440000 | L18: =GETPIVOTDATA("Total Fees",$B$4,"Team","TAX")-K18 -> #REF! | M18: Vertex Upgrade; E-Invoice 4 Countries
B19: Technology | C19: 5913530 | E19: 4122162 | F19: 10035692 | I19: =GETPIVOTDATA("Total Fees",$B$4,"Team","Technology ")/GETPIVOTDATA("Total Fees",$B$4) -> #REF! | J19: 0.18 | K19: =J19*$F$22 -> 7740000 | L19: =GETPIVOTDATA("Total Fees",$B$4,"Team","Technology ")-K19 -> #REF!
B20: Validation | C20: 36225 | E20: 91742 | F20: 127967 | I20: =GETPIVOTDATA("Total Fees",$B$4,"Team","Validation")/GETPIVOTDATA("Total Fees",$B$4) -> #REF! | J20: 0.003 | K20: =J20*$F$22 -> 129000 | L20: =GETPIVOTDATA("Total Fees",$B$4,"Team","Validation")-K20 -> #REF!
B21: Total Result | C21: 23526277 | D21: 512358 | E21: 24399215 | F21: 48437850 | I21: =SUM(I6:I20) -> #REF! | J21: =SUM(J6:J20) -> 1 | K21: =SUM(K6:K20) -> 43000000 | L21: =SUM(L6:L20) -> #REF!
E22: Target Fees | F22: 43000000
B25: Sum of Planning Fees | C25: Geography
B26: Team | C26: India | D26: Mexico | E26: US | F26: US - Project | G26: Total Result | P26: PTD % | Q26: Total %
B27: Analytics | C27: 56250 | E27: 122400 | G27: 178650 | N27: PTD Total | O27: 6240000 | Q27: =O27/$O$33 -> 0.14511628
B28: Data | C28: 43740 | E28: 146880 | G28: 190620 | N28: LOG | O28: 2430000 | P28: =O28/$O$27 -> 0.38942308 | Q28: =O28/$O$33 -> 0.056511628
B29: Deployment | C29: 0 | E29: 0 | G29: 0 | N29: MFG | O29: 3420000 | P29: =O29/$O$27 -> 0.54807692 | Q29: =O29/$O$33 -> 0.079534884
B30: OCM | C30: 0 | D30: 24114 | E30: 157264 | G30: 181378 | N30: PLAN | O30: 488340 | P30: =O30/$O$27 -> 0.078259615 | Q30: =O30/$O$33 -> 0.011356744
B31: OTC | C31: 44550 | E31: 134640 | G31: 179190
B32: PMO | C32: 92496 | E32: 322284 | G32: 414780
B33: PTD | C33: 209385 | E33: 287280 | G33: 496665 | N33: Total | O33: 43000000
B34: PTP | C34: 115965 | E34: 134640 | G34: 250605
B35: RTR | C35: 84330 | E35: 109440 | G35: 193770
B36: S&R | C36: 21600 | E36: 117000 | G36: 138600
B37: Security | C37: 72850 | E37: 193460 | G37: 266310
B38: Solution Architecture | C38: 31950 | E38: 131328 | G38: 163278
B39: TAX | C39: 32850 | E39: 139500 | G39: 172350
B40: Technology | C40: 51900 | E40: 305280 | F40: 0 | G40: 357180
B41: Validation | C41: 36225 | E41: 91742 | G41: 127967
B42: Total Result | C42: 894091 | D42: 24114 | E42: 2393138 | F42: 0 | G42: 3311343
B47: Team | C47: Sum of Total Hours
B48: Analytics | C48: 15640
B49: Data | C49: 11510
...

Sheet Staffing
B3: Fees | C3: =SUM(Q10:Q228) -> 96875700 | E3: Technology | F3: =SUMIFS($S$10:$S$146,$X$10:$X$146,E3)/$C$4 -> #VALUE! | BB3: Scoping and Planning Phase | CB3: Build 1 | CF3: Build 2 | CJ3: Build 3 | CN3: Build 4 | CR3: Build 5 | CV3: Build 6 | DC3: SIT 1 | DL3: SIT 2 | DW3: UAT/Val Test | EF3: Dry Run
B4: Hours | C4: =SUM(S10:S228) -> #VALUE! | E4: Consulting | F4: =SUMIFS($S$10:$S$146,$X$10:$X$146,E4)/$C$4 -> #VALUE! | BL4: Prep | BN4: Design 1 | BT4: Design 2 | BX4: Design 3 | CB4: Design 4 | CF4: Design 5 | CZ4: MC1 | DI4: MC2 | DT4: MC3 | EC4: CS | EL4: FPC | EO4: HYC
B5: RPH | C5: =C3/C4 -> #VALUE! | E5: Tax | F5: =SUMIFS($S$10:$S$146,$X$10:$X$146,E5)/$C$4 -> #VALUE!
FQ6: P9 | FR6: P10 | FS6: P11 | FT6: P12 | FU6: P13 | FV6: P1 | FW6: P2 | FX6: P3 | FY6: P4 | FZ6: P5 | GA6: P6 | GB6: P7 | GC6: P8 | GD6: P9 | GE6: P10 | GF6: P11 | GG6: P12 | GH6: P13 | GI6: P1 | GJ6: P2 | GK6: P3 | GL6: P4 | GM6: P5 | GN6: P6 | GO6: P7 | GP6: P8 | GQ6: P9 | GR6: P10 | GS6: P11 | GT6: P12 | GU6: P13 | GV6: P1 | GW6: P2 | GX6: P3 | GY6: P4 | GZ6: P5 | HA6: P6 | HB6: P7 | HC6: P8 | HD6: P9 | HE6: P10
AB7: FY26 | AC7: FY26 | AD7: FY26 | AE7: FY26 | AF7: FY26 | AG7: FY26 | AH7: FY26 | AI7: FY26 | AJ7: FY26 | AK7: FY26 | AL7: FY26 | AM7: FY26 | AN7: FY26 | AO7: FY26 | AP7: FY26 | AQ7: FY26 | AR7: FY26 | AS7: FY27 | AT7: FY27 | AU7: FY27 | AV7: FY27 | AW7: FY27 | AX7: FY27 | AY7: FY27 | AZ7: FY27 | BA7: FY27 | BB7: FY27 | BC7: FY27 | BD7: FY27 | BE7: FY27 | BF7: FY27 | BG7: FY27 | BH7: FY27 | BI7: FY27 | BJ7: FY27 | BK7: FY27 | BL7: FY27 | BM7: FY27 | BN7: FY27 | BO7: FY27 | BP7: FY27 | BQ7: FY27 | BR7: FY27 | BS7: FY27 | BT7: FY27 | BU7: FY27 | BV7: FY27 | BW7: FY27 | BX7: FY27 | BY7: FY27 | BZ7: FY27 | CA7: FY27 | CB7: FY27 | CC7: FY27 | CD7: FY27 | CE7: FY27 | CF7: FY27 | CG7: FY27 | CH7: FY27 | CI7: FY27 | CJ7: FY27 | CK7: FY27 | CL7: FY27 | CM7: FY27 | CN7: FY28 | CO7: FY28 | CP7: FY28 | CQ7: FY28 | CR7: FY28 | CS7: FY28 | CT7: FY28 | CU7: FY28 | CV7: FY28 | CW7: FY28 | CX7: FY28 | CY7: FY28 | CZ7: FY28 | DA7: FY28 | DB7: FY28 | DC7: FY28 | DD7: FY28 | DE7: FY28 | DF7: FY28 | DG7: FY28 | DH7: FY28 | DI7: FY28 | DJ7: FY28 | DK7: FY28 | DL7: FY28 | DM7: FY28 | DN7: FY28 | DO7: FY28 | DP7: FY28 | DQ7: FY28 | DR7: FY28 | DS7: FY28 | DT7: FY28 | DU7: FY28 | DV7: FY28 | DW7: FY28 | DX7: FY28 | DY7: FY28 | DZ7: FY28 | EA7: FY28 | EB7: FY28 | EC7: FY28 | ED7: FY28 | EE7: FY28 | EF7: FY28 | EG7: FY28 | EH7: FY28 | EI7: FY28 | EJ7: FY28 | EK7: FY28 | EL7: FY28 | EM7: FY28 | EN7: FY29-P1 | EO7: FY29 | EP7: FY29 | EQ7: FY29 | ER7: FY29 | ES7: FY29 | ET7: FY29 | EU7: FY29 | EV7: FY29 | EW7: FY29 | EX7: FY29 | EY7: FY29 | EZ7: FY29 | FA7: FY29 | FB7: FY29 | FC7: FY29 | FD7: FY29 | FE7: FY29 | FF7: FY29 | FG7: FY29 | FH7: FY29 | FI7: FY29 | FJ7: FY29 | FK7: FY29 | FL7: FY29 | FM7: FY29 | FN7: FY29 | FO7: FY29 | FP7: Start Date | FQ7: 46033 | FR7: 46061 | FS7: 46089 | FT7: 46117 | FU7: 46145 | FV7: 46173 | FW7: 46201 | FX7: 46229 | FY7: 46257 | FZ7: 46285 | GA7: 46313 | GB7: 46341 | GC7: 46369 | GD7: 46397 | GE7: 46425 | GF7: 46453 | GG7: 46481 | GH7: 46509 | GI7: 46537 | GJ7: 46565 | GK7: 46593 | GL7: 46621 | GM7: 46649 | GN7: 46677 | GO7: 46705 | GP7: 46733
Q8: =SUBTOTAL(9,Q10:Q228) -> 96875700 | S8: =SUBTOTAL(9,S10:S228) -> #VALUE! | X8: Rate Information | AB8: FY26-P09 | AC8: FY26-P10 | AD8: FY26-P10 | AE8: FY26-P10 | AF8: FY26-P10 | AG8: FY26-P11 | AH8: FY26-P11 | AI8: FY26-P11 | AJ8: FY26-P11 | AK8: FY26-P12 | AL8: FY26-P12 | AM8: FY26-P12 | AN8: FY26-P12 | AO8: FY26-P13 | AP8: FY26-P13 | AQ8: FY26-P13 | AR8: FY26-P13 | AS8: FY27-P01 | AT8: FY27-P01 | AU8: FY27-P2 | AV8: FY27-P3 | AW8: FY27-P3 | AX8: FY27-P3 | AY8: FY27-P3 | AZ8: FY27-P4 | BA8: FY27-P4 | BB8: FY27-P4 | BC8: FY27-P4 | BD8: FY27-P5 | BE8: FY27-P5 | BF8: FY27-P5 | BG8: FY27-P5 | BH8: FY27-P6 | BI8: FY27-P6 | BJ8: FY27-P6 | BK8: FY27-P6 | BL8: FY27-P7 | BM8: FY27-P7 | BN8: FY27-P7 | BO8: FY27-P7 | BP8: FY27-P8 | BQ8: FY27-P8 | BR8: FY27-P8 | BS8: FY27-P8 | BT8: FY27-P9 | BU8: FY27-P9 | BV8: FY27-P9 | BW8: FY27-P9 | BX8: FY27-P10 | BY8: FY27-P10 | BZ8: FY27-P10 | CA8: FY27-P10 | CB8: FY27-P11 | CC8: FY27-P11 | CD8: FY27-P11 | CE8: FY27-P11 | CF8: FY27-P12 | CG8: FY27-P12 | CH8: FY27-P12 | CI8: FY27-P12 | CJ8: FY27-P13 | CK8: FY27-P13 | CL8: FY27-P13 | CM8: FY27-P13 | CN8: FY28-P1 | CO8: FY28-P1 | CP8: FY28-P1 | CQ8: FY28-P1 | CR8: FY28-P2 | CS8: FY28-P2 | CT8: FY28-P2 | CU8: FY28-P2 | CV8: FY28-P3 | CW8: FY28-P3 | CX8: FY28-P3 | CY8: FY28-P3 | CZ8: FY28-P4 | DA8: FY28-P4 | DB8: FY28-P4 | DC8: FY28-P4 | DD8: FY28-P5 | DE8: FY28-P5 | DF8: FY28-P5 | DG8: FY28-P5 | DH8: FY28-P6 | DI8: FY28-P6 | DJ8: FY28-P6 | DK8: FY28-P6 | DL8: FY28-P7 | DM8: FY28-P7 | DN8: FY28-P7 | DO8: FY28-P7 | DP8: FY28-P8 | DQ8: FY28-P8 | DR8: FY28-P8 | DS8: FY28-P8 | DT8: FY28-P9 | DU8: FY28-P9 | DV8: FY28-P9 | DW8: FY28-P9 | DX8: FY28-P10 | DY8: FY28-P10 | DZ8: FY28-P10 | EA8: FY28-P10 | EB8: FY28-P11 | EC8: FY28-P11 | ED8: FY28-P11 | EE8: FY28-P11 | EF8: FY28-P12 | EG8: FY28-P12 | EH8: FY28-P12 | EI8: FY28-P12 | EJ8: FY28-P13 | EK8: FY28-P13 | EL8: FY28-P13 | EM8: FY28-P13 | EN8: FY29-P1 | EO8: FY29-P1 | EP8: FY29-P1 | EQ8: FY29-P1 | ER8: FY29-P2 | ES8: FY29-P2 | ET8: FY29-P2 | EU8: FY29-P2 | EV8: FY29-P3 | EW8: FY29-P3 | EX8: FY29-P3 | EY8: FY29-P3 | EZ8: FY29-P4 | FA8: FY29-P4 | FB8: FY29-P4 | FC8: FY29-P4 | FD8: FY29-P5 | FE8: FY29-P5 | FF8: FY29-P5 | FG8: FY29-P5 | FH8: FY29-P6 | FI8: FY29-P6 | FJ8: FY29-P6 | FK8: FY29-P6 | FL8: FY29-P7 | FM8: FY29-P7 | FN8: FY29-P7 | FO8: FY29-P7 | FP8: End Date | FQ8: 46060 | FR8: 46088 | FS8: 46116 | FT8: 46144 | FU8: 46172 | FV8: 46200 | FW8: 46228 | FX8: 46256 | FY8: 46284 | FZ8: 46312 | GA8: 46340 | GB8: 46368 | GC8: 46396 | GD8: 46424 | GE8: 46452 | GF8: 46480 | GG8: 46508 | GH8: 46536 | GI8: 46564 | GJ8: 46592 | GK8: 46620 | GL8: 46648 | GM8: 46676 | GN8: 46704 | GO8: 46732 | GP8: 46760 | HF8: =SUM(HF10:HF175) -> #VALUE! | HG8: =SUM(HG10:HG175) -> #VALUE!
B9: Process or Enabling | C9: Team | D9: Sub-Team | E9: Role Name | F9: Location | G9: Business | H9: Offering Portfolio | I9: Offering | J9: Geography | K9: Job Family | L9: Sub Family | M9: Deloitte Level | N9: Phase / Work Team | O9: Rate Helper (do not delete) | P9: Client Role | Q9: Total Fees | R9: Planning Fees | S9: CV Total Hrs Not Actual Total Hours | T9: Total Hours | U9: Staffing Role | V9: Years of Experience | W9: Staffing Location | X9: Rate Type | Y9: Role | Z9: Rate Card Level | AA9: PM Avg Rates | AB9: Rate Card Yr2 Rates | AC9: 46090 | AD9: 46097 | AE9: 46104 | AF9: 46111 | AG9: 46118 | AH9: 46125 | AI9: 46132 | AJ9: 46139 | AK9: 46146 | AL9: 46153 | AM9: 46160 | AN9: 46167 | AO9: 46174 | AP9: 46181 | AQ9: 46188 | AR9: 46195 | AS9: 46202 | AT9: 46209 | AU9: 46216 | AV9: 46223 | AW9: 46230 | AX9: 46237 | AY9: 46244 | AZ9: 46251 | BA9: 46258 | BB9: 46265 | BC9: 46272 | BD9: 46279 | BE9: 46286 | BF9: 46293 | BG9: 46300 | BH9: 46307 | BI9: 46314 | BJ9: 46321 | BK9: 46328 | BL9: 46335 | BM9: 46342 | BN9: 46349 | BO9: 46356 | BP9: 46363 | BQ9: 46370 | BR9: 46377 | BS9: 46384 | BT9: 46391 | BU9: 46398 | BV9: 46405 | BW9: 46412 | BX9: 46419 | BY9: 46426 | BZ9: 46433 | CA9: 46440 | CB9: 46447 | CC9: 46454 | CD9: 46461 | CE9: 46468 | CF9: 46475 | CG9: 46482 | CH9: 46489 | CI9: 46496 | CJ9: 46503 | CK9: 46510 | CL9: 46517 | CM9: 46524 | CN9: 46531 | CO9: 46538 | CP9: 46545 | CQ9: 46552 | CR9: 46559 | CS9: 46566 | CT9: 46573 | CU9: 46580 | CV9: 46587 | CW9: 46594 | CX9: 46601 | CY9: 46608 | CZ9: 46615 | DA9: 46622 | DB9: 46629 | DC9: 46636 | DD9: 46643 | DE9: 46650 | DF9: 46657 | DG9: 46664 | DH9: 46671 | DI9: 46678 | DJ9: 46685 | DK9: 46692 | DL9: 46699 | DM9: 46706 | DN9: 46713 | DO9: 46720 | DP9: 46727 | DQ9: 46734 | DR9: 46741 | DS9: 46748 | DT9: 46755 | DU9: 46762 | DV9: 46769 | DW9: 46776 | DX9: 46783 | DY9: 46790 | DZ9: 46797 | EA9: 46804 | EB9: 46811 | EC9: 46818 | ED9: 46825 | EE9: 46832 | EF9: 46839 | EG9: 46846 | EH9: 46853 | EI9: 46860 | EJ9: 46867 | EK9: 46874 | EL9: 46881 | EM9: 46888 | EN9: 46895 | EO9: 46902 | EP9: 46909 | EQ9: 46916 | ER9: 46923 | ES9: 46930 | ET9: 46937 | EU9: 46944 | EV9: 46951 | EW9: 46958 | EX9: 46965 | EY9: 46972 | EZ9: 46979 | FA9: 46986 | FB9: 46993 | FC9: 47000 | FD9: 47007 | FE9: 47014 | FF9: 47021 | FG9: 47028 | FH9: 47035 | FI9: 47042 | FJ9: 47049 | FK9: 47056 | FL9: 47063 | FM9: 47070 | FN9: 47077 | FO9: 47084 | FP9: 47091 | FQ9: FY27-P4 | FR9: FY27-P5 | FS9: FY27-P6 | FT9: FY27-P7 | FU9: FY27-P8 | FV9: FY27-P9 | FW9: FY27-P10 | FX9: FY27-P11 | FY9: FY27-P12 | FZ9: FY27-P13 | GA9: FY28-P1 | GB9: FY28-P2 | GC9: FY28-P3 | GD9: FY28-P4 | GE9: FY28-P5 | GF9: FY28-P6 | GG9: FY28-P7 | GH9: FY28-P8 | GI9: FY28-P9 | GJ9: FY28-P10 | GK9: FY28-P11 | GL9: FY28-P12 | GM9: FY28-P13 | GN9: FY29-P1 | GO9: FY29-P2 | GP9: FY28-P8 | GQ9: FY28-P9 | GR9: FY28-P10 | GS9: FY28-P11 | GT9: FY28-P12 | GU9: FY28-P13 | GV9: FY29-P1 | GW9: FY29-P2 | GX9: FY29-P3 | GY9: FY29-P4 | GZ9: FY29-P5 | HA9: FY29-P6 | HB9: FY29-P7 | HC9: FY29-P8 | HD9: FY29-P9 | HE9: FY29-P10 | HF9: Total | HG9: Check
B10: Enabling | C10: PMO | D10: PMO | E10: Project Sponsor | F10: US | G10: Consulting Services | H10: Enterprise Performance | I10: SAP | J10: US | K10: Package and Technology Enablement | L10: Package Program and Solution Management | M10: LMD - Managing Director | N10: =_xlfn.CONCAT(C10,"-",D10) -> PMO-PMO | O10: =_xlfn.CONCAT(Y10,"-",Z10,"-",F10,"-",X10) -> Technology-Principal-US-Consulting | P10: =_xlfn.CONCAT(C10," - ",Y10) -> PMO - Technology | Q10: =AB10*SUM(AZ10:ET10) -> 62046 | R10: =AB10*SUM(BC10:BN10) -> 4596 | S10: =SUM(GP10:HN10) -> #VALUE! | T10: =SUM(AZ10:EZ10) -> 162 | U10: =_xlfn.CONCAT(Y10," - ",Z10) -> Technology - Principal | V10: =VLOOKUP(O10,$B$187:$H$848,4,0) -> 15+ years | W10: =IF(F10="US", "Onshore",IF(F10="India","Offshore", "Nearshore")) -> Onshore | X10: Consulting | Y10: Technology | Z10: Principal | AA10: =[1]Resourcing!QD14 -> 0 | AB10: =IFERROR(VLOOKUP(O10,$B$187:$S$848,6,FALSE()),"combination not found") -> 383 | BC10: 1 | BD10: 1 | BE10: 1 | BF10: 1 | BG10: 1 | BH10: 1 | BI10: 1 | BJ10: 1 | BK10: 1 | BL10: 1 | BM10: 1 | BN10: 1 | BO10: 2 | BP10: 2 | BQ10: 2 | BT10: 2 | BU10: 2 | BV10: 2 | BW10: 2 | BX10: 2 | BY10: 2 | BZ10: 2 | CA10: 2 | CB10: 2 | CC10: 2 | CD10: 2 | CE10: 2 | CF10: 2 | CG10: 2 | CH10: 2 | CI10: 2 | CJ10: 2 | CK10: 2 | CL10: 2 | CM10: 2 | CN10: 2 | CO10: 2 | CP10: 2 | CQ10: 2 | CR10: 2 | CS10: 2 | CT10: 2 | CU10: 2 | CV10: 2 | CW10: 2 | CX10: 2 | CY10: 2 | CZ10: 2 | DA10: 2 | DB10: 2 | DC10: 2 | DD10: 2 | DE10: 2 | DF10: 2 | DG10: 2 | DH10: 2 | DI10: 2 | DJ10: 2 | DK10: 2 | DL10: 2 | DM10: 2 | DN10: 2 | DO10: 2 | DP10: 2 | DQ10: 2 | DT10: 2 | DU10: 2 | DV10: 2 | DW10: 2 | DX10: 2 | DY10: 2 | DZ10: 2 | EA10: 2 | EB10: 2 | EC10: 2 | ED10: 2 | EE10: 2 | EF10: 2 | EG10: 2 | EH10: 2 | EI10: 2 | EJ10: 2 | EK10: 2 | EL10: 2 | EM10: 2 | EN10: 2 | EO10: 2 | FQ10: =SUMIF($AC$11:$FP$11,FQ$12,$AC10:$FP10) -> #VALUE! | FR10: =SUMIF($AC$11:$FP$11,FR$12,$AC10:$FP10) -> #VALUE! | FS10: =SUMIF($AC$11:$FP$11,FS$12,$AC10:$FP10) -> #VALUE! | FT10: =SUMIF($AC$11:$FP$11,FT$12,$AC10:$FP10) -> #VALUE! | FU10: =SUMIF($AC$11:$FP$11,FU$12,$AC10:$FP10) -> #VALUE! | FV10: =SUMIF($AC$11:$FP$11,FV$12,$AC10:$FP10) -> #VALUE! | FW10: =SUMIF($AC$11:$FP$11,FW$12,$AC10:$FP10) -> #VALUE! | FX10: =SUMIF($AC$11:$FP$11,FX$12,$AC10:$FP10) -> #VALUE! | ... GO10: =SUMIF($AC$11:$FP$11,GO$12,$AC10:$FP10) -> #VALUE! | GP10: =SUMIF($AB$8:$FO$8,GP$9,$AB10:$FO10) -> 4 | GQ10: =SUMIF($AB$8:$FO$8,GQ$9,$AB10:$FO10) -> 8 | GR10: =SUMIF($AB$8:$FO$8,GR$9,$AB10:$FO10) -> 8 | GS10: =SUMIF($AB$8:$FO$8,GS$9,$AB10:$FO10) -> 8 | GT10: =SUMIF($AB$8:$FO$8,GT$9,$AB10:$FO10) -> 8 | GU10: =SUMIF($AB$8:$FO$8,GU$9,$AB10:$FO10) -> 8 | GV10: =SUMIF($AB$8:$FO$8,GV$9,$AB10:$FO10) -> 4 | GW10: =SUMIF($AB$8:$FO$8,GW$9,$AB10:$FO10) -> 0 | ... HE10: =SUMIF($AB$8:$FO$8,HE$9,$AB10:$FO10) -> 0 | HF10: =SUM(FQ10:HE10) -> #VALUE! | HG10: =HF10-S10 -> #VALUE!
B11: Enabling | C11: PMO | D11: PMO | E11: Engagement Lead | F11: US | G11: Consulting Services | H11: Enterprise Performance | I11: SAP | J11: US | K11: Package and Technology Enablement | L11: Package Program and Solution Management | M11: LMD - Managing Director | N11: =_xlfn.CONCAT(C11,"-",D11) -> PMO-PMO | O11: =_xlfn.CONCAT(Y11,"-",Z11,"-",F11,"-",X11) -> Technology-Managing Director-US-Consulting | P11: =_xlfn.CONCAT(C11," - ",Y11) -> PMO - Technology | Q11: =AB11*SUM(AZ11:ET11) -> 524710 | R11: =AB11*SUM(BC11:BN11) -> 45960 | S11: =SUM(GP11:HN11) -> #VALUE! | T11: =SUM(AZ11:EZ11) -> 1370 | U11: =_xlfn.CONCAT(Y11," - ",Z11) -> Technology - Managing Director | V11: =VLOOKUP(O11,$B$187:$H$848,4,0) -> 10-15 years | W11: =IF(F11="US", "Onshore",IF(F11="India","Offshore", "Nearshore")) -> Onshore | X11: Consulting | Y11: Technology | Z11: Managing Director | AA11: =[1]Resourcing!QD15 -> 0 | AB11: =IFERROR(VLOOKUP(O11,$B$187:$S$848,6,FALSE()),"combination not found") -> 383 | BC11: 10 | BD11: 10 | BE11: 10 | BF11: 10 | BG11: 10 | BH11: 10 | BI11: 10 | BJ11: 10 | BK11: 10 | BL11: 10 | BM11: 10 | BN11: 10 | BO11: 16 | BP11: 16 | BQ11: 16 | BT11: 16 | BU11: 16 | BV11: 16 | BW11: 16 | BX11: 16 | BY11: 16 | BZ11: 16 | CA11: 16 | CB11: 16 | CC11: 16 | CD11: 16 | CE11: 16 | CF11: 16 | CG11: 16 | CH11: 16 | CI11: 16 | CJ11: 16 | CK11: 16 | CL11: 16 | CM11: 16 | CN11: 16 | CO11: 16 | CP11: 16 | CQ11: 16 | CR11: 16 | CS11: 16 | CT11: 16 | CU11: 16 | CV11: 16 | CW11: 16 | CX11: 16 | CY11: 16 | CZ11: 16 | DA11: 16 | DB11: 16 | DC11: 16 | DD11: 16 | DE11: 16 | DF11: 16 | DG11: 16 | DH11: 16 | DI11: 16 | DJ11: 16 | DK11: 16 | DL11: 16 | DM11: 16 | DN11: 16 | DO11: 16 | DP11: 16 | DQ11: 16 | DT11: 16 | DU11: 16 | DV11: 16 | DW11: 16 | DX11: 16 | DY11: 16 | DZ11: 16 | EA11: 16 | EB11: 16 | EC11: 16 | ED11: 16 | EE11: 16 | EF11: 16 | EG11: 16 | EH11: 16 | EI11: 16 | EJ11: 16 | EK11: 16 | EL11: 16 | EM11: 16 | EN11: 16 | EO11: 16 | EP11: 10 | EQ11: 10 | ER11: 10 | ES11: 10 | ET11: 10 | FQ11: =SUMIF($AC$11:$FP$11,FQ$12,$AC11:$FP11) -> #VALUE! | FR11: =SUMIF($AC$11:$FP$11,FR$12,$AC11:$FP11) -> #VALUE! | FS11: =SUMIF($AC$11:$FP$11,FS$12,$AC11:$FP11) -> #VALUE! | FT11: =SUMIF($AC$11:$FP$11,FT$12,$AC11:$FP11) -> #VALUE! | FU11: =SUMIF($AC$11:$FP$11,FU$12,$AC11:$FP11) -> #VALUE! | FV11: =SUMIF($AC$11:$FP$11,FV$12,$AC11:$FP11) -> #VALUE! | FW11: =SUMIF($AC$11:$FP$11,FW$12,$AC11:$FP11) -> #VALUE! | FX11: =SUMIF($AC$11:$FP$11,FX$12,$AC11:$FP11) -> #VALUE! | ... GO11: =SUMIF($AC$11:$FP$11,GO$12,$AC11:$FP11) -> #VALUE! | GP11: =SUMIF($AB$8:$FO$8,GP$9,$AB11:$FO11) -> 32 | GQ11: =SUMIF($AB$8:$FO$8,GQ$9,$AB11:$FO11) -> 64 | GR11: =SUMIF($AB$8:$FO$8,GR$9,$AB11:$FO11) -> 64 | GS11: =SUMIF($AB$8:$FO$8,GS$9,$AB11:$FO11) -> 64 | GT11: =SUMIF($AB$8:$FO$8,GT$9,$AB11:$FO11) -> 64 | GU11: =SUMIF($AB$8:$FO$8,GU$9,$AB11:$FO11) -> 64 | GV11: =SUMIF($AB$8:$FO$8,GV$9,$AB11:$FO11) -> 52 | GW11: =SUMIF($AB$8:$FO$8,GW$9,$AB11:$FO11) -> 30 | ... HE11: =SUMIF($AB$8:$FO$8,HE$9,$AB11:$FO11) -> 0 | HF11: =SUM(FQ11:HE11) -> #VALUE! | HG11: =HF11-S11 -> #VALUE!
B12: Enabling | C12: PMO | D12: PMO | E12: Program Manager | F12: US | G12: Consulting Services | H12: Enterprise Performance | I12: SAP | J12: US | K12: Package and Technology Enablement | L12: Package Functional Transformation | M12: L65 - Senior Manager | N12: =_xlfn.CONCAT(C12,"-",D12) -> PMO-PMO | O12: =_xlfn.CONCAT(Y12,"-",Z12,"-",F12,"-",X12) -> Technology-Senior Manager-US-Consulting | P12: =_xlfn.CONCAT(C12," - ",Y12) -> PMO - Technology | Q12: =AB12*SUM(AZ12:ET12) -> 979488 | R12: =AB12*SUM(BC12:BN12) -> 131328 | S12: =SUM(GP12:HN12) -> #VALUE! | T12: =SUM(AZ12:EZ12) -> 2864 | U12: =_xlfn.CONCAT(Y12," - ",Z12) -> Technology - Senior Manager | V12: =VLOOKUP(O12,$B$187:$H$848,4,0) -> 7-10 years | W12: =IF(F12="US", "Onshore",IF(F12="India","Offshore", "Nearshore")) -> Onshore | X12: Consulting | Y12: Technology | Z12: Senior Manager | AA12: =[1]Resourcing!QD16 -> 0 | AB12: =IFERROR(VLOOKUP(O12,$B$187:$S$848,6,FALSE()),"combination not found") -> 342 | BC12: 32 | BD12: 32 | BE12: 32 | BF12: 32 | BG12: 32 | BH12: 32 | BI12: 32 | BJ12: 32 | BK12: 32 | BL12: 32 | BM12: 32 | BN12: 32 | BO12: 32 | BP12: 32 | BQ12: 32 | BT12: 32 | BU12: 32 | BV12: 32 | BW12: 32 | BX12: 32 | BY12: 32 | BZ12: 32 | CA12: 32 | CB12: 32 | CC12: 32 | CD12: 32 | CE12: 32 | CF12: 32 | CG12: 32 | CH12: 32 | CI12: 32 | CJ12: 32 | CK12: 32 | CL12: 32 | CM12: 32 | CN12: 32 | CO12: 32 | CP12: 32 | CQ12: 32 | CR12: 32 | CS12: 32 | CT12: 32 | CU12: 32 | CV12: 32 | CW12: 32 | CX12: 32 | CY12: 32 | CZ12: 32 | DA12: 32 | DB12: 32 | DC12: 32 | DD12: 32 | DE12: 32 | DF12: 32 | DG12: 32 | DH12: 32 | DI12: 32 | DJ12: 32 | DK12: 32 | DL12: 32 | DM12: 32 | DN12: 32 | DO12: 32 | DP12: 32 | DQ12: 32 | DT12: 32 | DU12: 32 | DV12: 32 | DW12: 32 | DX12: 32 | DY12: 32 | DZ12: 32 | EA12: 32 | EB12: 32 | EC12: 32 | ED12: 32 | EE12: 32 | EF12: 32 | EG12: 32 | EH12: 32 | EI12: 32 | EJ12: 32 | EK12: 32 | EL12: 32 | EM12: 32 | EN12: 32 | EO12: 32 | EP12: 16 | EQ12: 16 | ER12: 16 | ES12: 16 | ET12: 16 | FQ12: =SUMIF($AC$11:$FP$11,FQ$12,$AC12:$FP12) -> #VALUE! | FR12: =SUMIF($AC$11:$FP$11,FR$12,$AC12:$FP12) -> #VALUE! | FS12: =SUMIF($AC$11:$FP$11,FS$12,$AC12:$FP12) -> #VALUE! | FT12: =SUMIF($AC$11:$FP$11,FT$12,$AC12:$FP12) -> #VALUE! | FU12: =SUMIF($AC$11:$FP$11,FU$12,$AC12:$FP12) -> #VALUE! | FV12: =SUMIF($AC$11:$FP$11,FV$12,$AC12:$FP12) -> #VALUE! | FW12: =SUMIF($AC$11:$FP$11,FW$12,$AC12:$FP12) -> #VALUE! | FX12: =SUMIF($AC$11:$FP$11,FX$12,$AC12:$FP12) -> #VALUE! | ... GO12: =SUMIF($AC$11:$FP$11,GO$12,$AC12:$FP12) -> #VALUE! | GP12: =SUMIF($AB$8:$FO$8,GP$9,$AB12:$FO12) -> 64 | GQ12: =SUMIF($AB$8:$FO$8,GQ$9,$AB12:$FO12) -> 128 | GR12: =SUMIF($AB$8:$FO$8,GR$9,$AB12:$FO12) -> 128 | GS12: =SUMIF($AB$8:$FO$8,GS$9,$AB12:$FO12) -> 128 | GT12: =SUMIF($AB$8:$FO$8,GT$9,$AB12:$FO12) -> 128 | GU12: =SUMIF($AB$8:$FO$8,GU$9,$AB12:$FO12) -> 128 | GV12: =SUMIF($AB$8:$FO$8,GV$9,$AB12:$FO12) -> 96 | GW12: =SUMIF($AB$8:$FO$8,GW$9,$AB12:$FO12) -> 48 | ... HE12: =SUMIF($AB$8:$FO$8,HE$9,$AB12:$FO12) -> 0 | HF12: =SUM(FQ12:HE12) -> #VALUE! | HG12: =HF12-S12 -> #VALUE!
B13: Enabling | C13: PMO | D13: PMO | E13: PMO Consultant | F13: US | G13: Consulting Services | H13: Enterprise Performance | I13: SAP | J13: US | K13: Package and Technology Enablement | L13: Package Functional Transformation | M13: L25 - Analyst | N13: =_xlfn.CONCAT(C13,"-",D13) -> PMO-PMO | O13: =_xlfn.CONCAT(Y13,"-",Z13,"-",F13,"-",X13) -> Technology-Senior Consultant-US-Consulting | P13: =_xlfn.CONCAT(C13," - ",Y13) -> PMO - Technology | Q13: =AB13*SUM(AZ13:ET13) -> 1017900 | R13: =AB13*SUM(BC13:BN13) -> 140400 | S13: =SUM(GP13:HN13) -> #VALUE! | T13: =SUM(AZ13:EZ13) -> 3915 | U13: =_xlfn.CONCAT(Y13," - ",Z13) -> Technology - Senior Consultant | V13: =VLOOKUP(O13,$B$187:$H$848,4,0) -> 3-5 years | W13: =IF(F13="US", "Onshore",IF(F13="India","Offshore", "Nearshore")) -> Onshore | X13: Consulting | Y13: Technology | Z13: Senior Consultant | AA13: =[1]Resourcing!QD17 -> 402.16037 | AB13: =IFERROR(VLOOKUP(O13,$B$187:$S$848,6,FALSE()),"combination not found") -> 260 | BC13: 45 | BD13: 45 | BE13: 45 | BF13: 45 | BG13: 45 | BH13: 45 | BI13: 45 | BJ13: 45 | BK13: 45 | BL13: 45 | BM13: 45 | BN13: 45 | BO13: 45 | BP13: 45 | BQ13: 45 | BT13: 45 | BU13: 45 | BV13: 45 | BW13: 45 | BX13: 45 | BY13: 45 | BZ13: 45 | CA13: 45 | CB13: 45 | CC13: 45 | CD13: 45 | CE13: 45 | CF13: 45 | CG13: 45 | CH13: 45 | CI13: 45 | CJ13: 45 | CK13: 45 | CL13: 45 | CM13: 45 | CN13: 45 | CO13: 45 | CP13: 45 | CQ13: 45 | CR13: 45 | CS13: 45 | CT13: 45 | CU13: 45 | CV13: 45 | CW13: 45 | CX13: 45 | CY13: 45 | CZ13: 45 | DA13: 45 | DB13: 45 | DC13: 45 | DD13: 45 | DE13: 45 | DF13: 45 | DG13: 45 | DH13: 45 | DI13: 45 | DJ13: 45 | DK13: 45 | DL13: 45 | DM13: 45 | DN13: 45 | DO13: 45 | DP13: 45 | DQ13: 45 | DT13: 45 | DU13: 45 | DV13: 45 | DW13: 45 | DX13: 45 | DY13: 45 | DZ13: 45 | EA13: 45 | EB13: 45 | EC13: 45 | ED13: 45 | EE13: 45 | EF13: 45 | EG13: 45 | EH13: 45 | EI13: 45 | EJ13: 45 | EK13: 45 | EL13: 45 | EM13: 45 | EN13: 45 | EO13: 45 | FQ13: 90 | FR13: =SUMIF($AC$11:$FP$11,FR$12,$AC13:$FP13) -> #VALUE! | FS13: =SUMIF($AC$11:$FP$11,FS$12,$AC13:$FP13) -> #VALUE! | FT13: =SUMIF($AC$11:$FP$11,FT$12,$AC13:$FP13) -> #VALUE! | FU13: =SUMIF($AC$11:$FP$11,FU$12,$AC13:$FP13) -> #VALUE! | FV13: =SUMIF($AC$11:$FP$11,FV$12,$AC13:$FP13) -> #VALUE! | FW13: =SUMIF($AC$11:$FP$11,FW$12,$AC13:$FP13) -> #VALUE! | FX13: =SUMIF($AC$11:$FP$11,FX$12,$AC13:$FP13) -> #VALUE! | FY13: =SUMIF($AC$11:$FP$11,FY$12,$AC13:$FP13) -> #VALUE! | ... GO13: =SUMIF($AC$11:$FP$11,GO$12,$AC13:$FP13) -> #VALUE! | GP13: =SUMIF($AB$8:$FO$8,GP$9,$AB13:$FO13) -> 90 | GQ13: =SUMIF($AB$8:$FO$8,GQ$9,$AB13:$FO13) -> 180 | GR13: =SUMIF($AB$8:$FO$8,GR$9,$AB13:$FO13) -> 180 | GS13: =SUMIF($AB$8:$FO$8,GS$9,$AB13:$FO13) -> 180 | GT13: =SUMIF($AB$8:$FO$8,GT$9,$AB13:$FO13) -> 180 | GU13: =SUMIF($AB$8:$FO$8,GU$9,$AB13:$FO13) -> 180 | GV13: =SUMIF($AB$8:$FO$8,GV$9,$AB13:$FO13) -> 90 | GW13: =SUMIF($AB$8:$FO$8,GW$9,$AB13:$FO13) -> 0 | ... HE13: =SUMIF($AB$8:$FO$8,HE$9,$AB13:$FO13) -> 0 | HF13: =SUM(FQ13:HE13) -> #VALUE! | HG13: =HF13-S13 -> #VALUE!
B14: Enabling | C14: PMO | D14: PMO | E14: Offshore Lead | F14: India | G14: Consulting Services | H14: Enterprise Performance | I14: SAP | J14: India | K14: Package and Technology Enablement | L14: Package Program and Solution Management | M14: LMD - Managing Director | N14: =_xlfn.CONCAT(C14,"-",D14) -> PMO-PMO | O14: =_xlfn.CONCAT(Y14,"-",Z14,"-",F14,"-",X14) -> Technology-Principal-India-Consulting | P14: =_xlfn.CONCAT(C14," - ",Y14) -> PMO - Technology | Q14: =AB14*SUM(AZ14:ET14) -> 95040 | R14: =AB14*SUM(BC14:BN14) -> 8640 | S14: =SUM(GP14:HN14) -> #VALUE! | T14: =SUM(AZ14:EZ14) -> 528 | U14: =_xlfn.CONCAT(Y14," - ",Z14) -> Technology - Principal | V14: =VLOOKUP(O14,$B$187:$H$848,4,0) -> 15+ years | W14: =IF(F14="US", "Onshore",IF(F14="India","Offshore", "Nearshore")) -> Offshore | X14: Consulting | Y14: Technology | Z14: Principal | AA14: =[1]Resourcing!QD18 -> 403.10063 | AB14: =IFERROR(VLOOKUP(O14,$B$187:$S$848,6,FALSE()),"combination not found") -> 180 | BC14: 4 | BD14: 4 | BE14: 4 | BF14: 4 | BG14: 4 | BH14: 4 | BI14: 4 | BJ14: 4 | BK14: 4 | BL14: 4 | BM14: 4 | BN14: 4 | BO14: 6 | BP14: 6 | BQ14: 6 | BT14: 6 | BU14: 6 | BV14: 6 | BW14: 6 | BX14: 6 | BY14: 6 | BZ14: 6 | CA14: 6 | CB14: 6 | CC14: 6 | CD14: 6 | CE14: 6 | CF14: 6 | CG14: 6 | CH14: 6 | CI14: 6 | CJ14: 6 | CK14: 6 | CL14: 6 | CM14: 6 | CN14: 6 | CO14: 6 | CP14: 6 | CQ14: 6 | CR14: 6 | CS14: 6 | CT14: 6 | CU14: 6 | CV14: 6 | CW14: 6 | CX14: 6 | CY14: 6 | CZ14: 6 | DA14: 6 | DB14: 6 | DC14: 6 | DD14: 6 | DE14: 6 | DF14: 6 | DG14: 6 | DH14: 6 | DI14: 6 | DJ14: 6 | DK14: 6 | DL14: 6 | DM14: 6 | DN14: 6 | DO14: 6 | DP14: 6 | DQ14: 6 | DT14: 6 | DU14: 6 | DV14: 6 | DW14: 6 | DX14: 6 | DY14: 6 | DZ14: 6 | EA14: 6 | EB14: 6 | EC14: 6 | ED14: 6 | EE14: 6 | EF14: 6 | EG14: 6 | EH14: 6 | EI14: 6 | EJ14: 6 | EK14: 6 | EL14: 6 | EM14: 6 | EN14: 6 | EO14: 6 | EP14: 6 | EQ14: 6 | ER14: 6 | ES14: 6 | ET14: 6 | FQ14: =SUMIF($AC$11:$FP$11,FQ$12,$AC14:$FP14) -> #VALUE! | FR14: =SUMIF($AC$11:$FP$11,FR$12,$AC14:$FP14) -> #VALUE! | FS14: =SUMIF($AC$11:$FP$11,FS$12,$AC14:$FP14) -> #VALUE! | FT14: =SUMIF($AC$11:$FP$11,FT$12,$AC14:$FP14) -> #VALUE! | FU14: =SUMIF($AC$11:$FP$11,FU$12,$AC14:$FP14) -> #VALUE! | FV14: =SUMIF($AC$11:$FP$11,FV$12,$AC14:$FP14) -> #VALUE! | FW14: =SUMIF($AC$11:$FP$11,FW$12,$AC14:$FP14) -> #VALUE! | FX14: =SUMIF($AC$11:$FP$11,FX$12,$AC14:$FP14) -> #VALUE! | ... GO14: =SUMIF($AC$11:$FP$11,GO$12,$AC14:$FP14) -> #VALUE! | GP14: =SUMIF($AB$8:$FO$8,GP$9,$AB14:$FO14) -> 12 | GQ14: =SUMIF($AB$8:$FO$8,GQ$9,$AB14:$FO14) -> 24 | GR14: =SUMIF($AB$8:$FO$8,GR$9,$AB14:$FO14) -> 24 | GS14: =SUMIF($AB$8:$FO$8,GS$9,$AB14:$FO14) -> 24 | GT14: =SUMIF($AB$8:$FO$8,GT$9,$AB14:$FO14) -> 24 | GU14: =SUMIF($AB$8:$FO$8,GU$9,$AB14:$FO14) -> 24 | GV14: =SUMIF($AB$8:$FO$8,GV$9,$AB14:$FO14) -> 24 | GW14: =SUMIF($AB$8:$FO$8,GW$9,$AB14:$FO14) -> 18 | ... HE14: =SUMIF($AB$8:$FO$8,HE$9,$AB14:$FO14) -> 0 | HF14: =SUM(FQ14:HE14) -> #VALUE! | HG14: =HF14-S14 -> #VALUE!
B15: Enabling | C15: PMO | D15: PMO | E15: Offshore GDM | F15: India | G15: Consulting Services | H15: Enterprise Performance | I15: SAP | J15: India | K15: Package and Technology Enablement | L15: Package Functional Transformation | M15: L65 - Senior Manager | N15: =_xlfn.CONCAT(C15,"-",D15) -> PMO-PMO | O15: =_xlfn.CONCAT(Y15,"-",Z15,"-",F15,"-",X15) -> Technology-Senior Manager-India-Consulting | P15: =_xlfn.CONCAT(C15," - ",Y15) -> PMO - Technology | Q15: =AB15*SUM(AZ15:ET15) -> 394496 | R15: =AB15*SUM(BC15:BN15) -> 51456 | S15: =SUM(GP15:HN15) -> #VALUE! | T15: =SUM(AZ15:EZ15) -> 2944 | U15: =_xlfn.CONCAT(Y15," - ",Z15) -> Technology - Senior Manager | V15: =VLOOKUP(O15,$B$187:$H$848,4,0) -> 7-10 years | W15: =IF(F15="US", "Onshore",IF(F15="India","Offshore", "Nearshore")) -> Offshore | X15: Consulting | Y15: Technology | Z15: Senior Manager | AA15: =[1]Resourcing!QD19 -> 380.11732 | AB15: =IFERROR(VLOOKUP(O15,$B$187:$S$848,6,FALSE()),"combination not found") -> 134 | BC15: 32 | BD15: 32 | BE15: 32 | BF15: 32 | BG15: 32 | BH15: 32 | BI15: 32 | BJ15: 32 | BK15: 32 | BL15: 32 | BM15: 32 | BN15: 32 | BO15: 32 | BP15: 32 | BQ15: 32 | BT15: 32 | BU15: 32 | BV15: 32 | BW15: 32 | BX15: 32 | BY15: 32 | BZ15: 32 | CA15: 32 | CB15: 32 | CC15: 32 | CD15: 32 | CE15: 32 | CF15: 32 | CG15: 32 | CH15: 32 | CI15: 32 | CJ15: 32 | CK15: 32 | CL15: 32 | CM15: 32 | CN15: 32 | CO15: 32 | CP15: 32 | CQ15: 32 | CR15: 32 | CS15: 32 | CT15: 32 | CU15: 32 | CV15: 32 | CW15: 32 | CX15: 32 | CY15: 32 | CZ15: 32 | DA15: 32 | DB15: 32 | DC15: 32 | DD15: 32 | DE15: 32 | DF15: 32 | DG15: 32 | DH15: 32 | DI15: 32 | DJ15: 32 | DK15: 32 | DL15: 32 | DM15: 32 | DN15: 32 | DO15: 32 | DP15: 32 | DQ15: 32 | DT15: 32 | DU15: 32 | DV15: 32 | DW15: 32 | DX15: 32 | DY15: 32 | DZ15: 32 | EA15: 32 | EB15: 32 | EC15: 32 | ED15: 32 | EE15: 32 | EF15: 32 | EG15: 32 | EH15: 32 | EI15: 32 | EJ15: 32 | EK15: 32 | EL15: 32 | EM15: 32 | EN15: 32 | EO15: 32 | EP15: 32 | EQ15: 32 | ER15: 32 | ES15: 32 | ET15: 32 | FQ15: =SUMIF($AC$11:$FP$11,FQ$12,$AC15:$FP15) -> #VALUE! | FR15: =SUMIF($AC$11:$FP$11,FR$12,$AC15:$FP15) -> #VALUE! | FS15: =SUMIF($AC$11:$FP$11,FS$12,$AC15:$FP15) -> #VALUE! | FT15: =SUMIF($AC$11:$FP$11,FT$12,$AC15:$FP15) -> #VALUE! | FU15: =SUMIF($AC$11:$FP$11,FU$12,$AC15:$FP15) -> #VALUE! | FV15: =SUMIF($AC$11:$FP$11,FV$12,$AC15:$FP15) -> #VALUE! | FW15: =SUMIF($AC$11:$FP$11,FW$12,$AC15:$FP15) -> #VALUE! | FX15: =SUMIF($AC$11:$FP$11,FX$12,$AC15:$FP15) -> #VALUE! | ... GO15: =SUMIF($AC$11:$FP$11,GO$12,$AC15:$FP15) -> #VALUE! | GP15: =SUMIF($AB$8:$FO$8,GP$9,$AB15:$FO15) -> 64 | GQ15: =SUMIF($AB$8:$FO$8,GQ$9,$AB15:$FO15) -> 128 | GR15: =SUMIF($AB$8:$FO$8,GR$9,$AB15:$FO15) -> 128 | GS15: =SUMIF($AB$8:$FO$8,GS$9,$AB15:$FO15) -> 128 | GT15: =SUMIF($AB$8:$FO$8,GT$9,$AB15:$FO15) -> 128 | GU15: =SUMIF($AB$8:$FO$8,GU$9,$AB15:$FO15) -> 128 | GV15: =SUMIF($AB$8:$FO$8,GV$9,$AB15:$FO15) -> 128 | GW15: =SUMIF($AB$8:$FO$8,GW$9,$AB15:$FO15) -> 96 | ... HE15: =SUMIF($AB$8:$FO$8,HE$9,$AB15:$FO15) -> 0 | HF15: =SUM(FQ15:HE15) -> #VALUE! | HG15: =HF15-S15 -> #VALUE!
B16: Enabling | C16: PMO | D16: PMO | E16: PMO Consultant | F16: India | G16: Consulting Services | H16: Enterprise Performance | I16: SAP | J16: India | K16: Package and Technology Enablement | L16: Package Functional Transformation | M16: L35 - Consultant | N16: =_xlfn.CONCAT(C16,"-",D16) -> PMO-PMO | O16: =_xlfn.CONCAT(Y16,"-",Z16,"-",F16,"-",X16) -> Technology-Consultant-India-Consulting | P16: =_xlfn.CONCAT(C16," - ",Y16) -> PMO - Technology | Q16: =AB16*SUM(AZ16:ET16) -> 248400 | R16: =AB16*SUM(BC16:BN16) -> 32400 | S16: =SUM(GP16:HN16) -> #VALUE! | T16: =SUM(AZ16:EZ16) -> 4140 | U16: =_xlfn.CONCAT(Y16," - ",Z16) -> Technology - Consultant | V16: =VLOOKUP(O16,$B$187:$H$848,4,0) -> 1-3 years | W16: =IF(F16="US", "Onshore",IF(F16="India","Offshore", "Nearshore")) -> Offshore | X16: Consulting | Y16: Technology | Z16: Consultant | AA16: =[1]Resourcing!QD20 -> 264.54736 | AB16: =IFERROR(VLOOKUP(O16,$B$187:$S$848,6,FALSE()),"combination not found") -> 60 | BC16: 45 | BD16: 45 | BE16: 45 | BF16: 45 | BG16: 45 | BH16: 45 | BI16: 45 | BJ16: 45 | BK16: 45 | BL16: 45 | BM16: 45 | BN16: 45 | BO16: 45 | BP16: 45 | BQ16: 45 | BT16: 45 | BU16: 45 | BV16: 45 | BW16: 45 | BX16: 45 | BY16: 45 | BZ16: 45 | CA16: 45 | CB16: 45 | CC16: 45 | CD16: 45 | CE16: 45 | CF16: 45 | CG16: 45 | CH16: 45 | CI16: 45 | CJ16: 45 | CK16: 45 | CL16: 45 | CM16: 45 | CN16: 45 | CO16: 45 | CP16: 45 | CQ16: 45 | CR16: 45 | CS16: 45 | CT16: 45 | CU16: 45 | CV16: 45 | CW16: 45 | CX16: 45 | CY16: 45 | CZ16: 45 | DA16: 45 | DB16: 45 | DC16: 45 | DD16: 45 | DE16: 45 | DF16: 45 | DG16: 45 | DH16: 45 | DI16: 45 | DJ16: 45 | DK16: 45 | DL16: 45 | DM16: 45 | DN16: 45 | DO16: 45 | DP16: 45 | DQ16: 45 | DT16: 45 | DU16: 45 | DV16: 45 | DW16: 45 | DX16: 45 | DY16: 45 | DZ16: 45 | EA16: 45 | EB16: 45 | EC16: 45 | ED16: 45 | EE16: 45 | EF16: 45 | EG16: 45 | EH16: 45 | EI16: 45 | EJ16: 45 | EK16: 45 | EL16: 45 | EM16: 45 | EN16: 45 | EO16: 45 | EP16: 45 | EQ16: 45 | ER16: 45 | ES16: 45 | ET16: 45 | FQ16: =SUMIF($AC$11:$FP$11,FQ$12,$AC16:$FP16) -> #VALUE! | FR16: =SUMIF($AC$11:$FP$11,FR$12,$AC16:$FP16) -> #VALUE! | FS16: =SUMIF($AC$11:$FP$11,FS$12,$AC16:$FP16) -> #VALUE! | FT16: =SUMIF($AC$11:$FP$11,FT$12,$AC16:$FP16) -> #VALUE! | FU16: =SUMIF($AC$11:$FP$11,FU$12,$AC16:$FP16) -> #VALUE! | FV16: =SUMIF($AC$11:$FP$11,FV$12,$AC16:$FP16) -> #VALUE! | FW16: =SUMIF($AC$11:$FP$11,FW$12,$AC16:$FP16) -> #VALUE! | FX16: =SUMIF($AC$11:$FP$11,FX$12,$AC16:$FP16) -> #VALUE! | ... GO16: =SUMIF($AC$11:$FP$11,GO$12,$AC16:$FP16) -> #VALUE! | GP16: =SUMIF($AB$8:$FO$8,GP$9,$AB16:$FO16) -> 90 | GQ16: =SUMIF($AB$8:$FO$8,GQ$9,$AB16:$FO16) -> 180 | GR16: =SUMIF($AB$8:$FO$8,GR$9,$AB16:$FO16) -> 180 | GS16: =SUMIF($AB$8:$FO$8,GS$9,$AB16:$FO16) -> 180 | GT16: =SUMIF($AB$8:$FO$8,GT$9,$AB16:$FO16) -> 180 | GU16: =SUMIF($AB$8:$FO$8,GU$9,$AB16:$FO16) -> 180 | GV16: =SUMIF($AB$8:$FO$8,GV$9,$AB16:$FO16) -> 180 | GW16: =SUMIF($AB$8:$FO$8,GW$9,$AB16:$FO16) -> 135 | ... HE16: =SUMIF($AB$8:$FO$8,HE$9,$AB16:$FO16) -> 0 | HF16: =SUM(FQ16:HE16) -> #VALUE! | HG16: =HF16-S16 -> #VALUE!
Q17: =AB17*SUM(AZ17:ET17) -> 0 | R17: =AB17*SUM(BC17:BN17) -> 0 | T17: =SUM(AZ17:EZ17) -> 0 | AA17: =[1]Resourcing!QD21 -> 179.31318 | FQ17: =SUMIF($AC$11:$FP$11,FQ$12,$AC17:$FP17) -> #VALUE! | FR17: =SUMIF($AC$11:$FP$11,FR$12,$AC17:$FP17) -> #VALUE! | FS17: =SUMIF($AC$11:$FP$11,FS$12,$AC17:$FP17) -> #VALUE! | FT17: =SUMIF($AC$11:$FP$11,FT$12,$AC17:$FP17) -> #VALUE! | FU17: =SUMIF($AC$11:$FP$11,FU$12,$AC17:$FP17) -> #VALUE! | FV17: =SUMIF($AC$11:$FP$11,FV$12,$AC17:$FP17) -> #VALUE! | FW17: =SUMIF($AC$11:$FP$11,FW$12,$AC17:$FP17) -> #VALUE! | FX17: =SUMIF($AC$11:$FP$11,FX$12,$AC17:$FP17) -> #VALUE! | ... GO17: =SUMIF($AC$11:$FP$11,GO$12,$AC17:$FP17) -> #VALUE!
B18: Process | C18: Solution Architecture | D18: Solution Delivery | E18: Solution Architect | F18: US | G18: Consulting Services | H18: Enterprise Performance | I18: SAP | J18: US | K18: Package and Technology Enablement | L18: Package Functional Transformation | M18: L65 - Senior Manager | N18: =_xlfn.CONCAT(C18,"-",D18) -> Solution Architecture-Solution Delivery | O18: =_xlfn.CONCAT(Y18,"-",Z18,"-",F18,"-",X18) -> Technology-Senior Manager-US-Consulting | P18: =_xlfn.CONCAT(C18," - ",Y18) -> Solution Architecture - Technology | Q18: =AB18*SUM(AZ18:ET18) -> 979488 | R18: =AB18*SUM(BC18:BN18) -> 131328 | S18: =SUM(GP18:HN18) -> 0 | T18: =SUM(AZ18:EZ18) -> 2864 | U18: =_xlfn.CONCAT(Y18," - ",Z18) -> Technology - Senior Manager | V18: =VLOOKUP(O18,$B$187:$H$848,4,0) -> 7-10 years | W18: =IF(F18="US", "Onshore",IF(F18="India","Offshore", "Nearshore")) -> Onshore | X18: Consulting | Y18: Technology | Z18: Senior Manager | AA18: =[1]Resourcing!QD22 -> 126.96174 | AB18: =IFERROR(VLOOKUP(O18,$B$187:$S$848,6,FALSE()),"combination not found") -> 342 | BC18: 32 | BD18: 32 | BE18: 32 | BF18: 32 | BG18: 32 | BH18: 32 | BI18: 32 | BJ18: 32 | BK18: 32 | BL18: 32 | BM18: 32 | BN18: 32 | BO18: 32 | BP18: 32 | BQ18: 32 | BT18: 32 | BU18: 32 | BV18: 32 | BW18: 32 | BX18: 32 | BY18: 32 | BZ18: 32 | CA18: 32 | CB18: 32 | CC18: 32 | CD18: 32 | CE18: 32 | CF18: 32 | CG18: 32 | CH18: 32 | CI18: 32 | CJ18: 32 | CK18: 32 | CL18: 32 | CM18: 32 | CN18: 32 | CO18: 32 | CP18: 32 | CQ18: 32 | CR18: 32 | CS18: 32 | CT18: 32 | CU18: 32 | CV18: 32 | CW18: 32 | CX18: 32 | CY18: 32 | CZ18: 32 | DA18: 32 | DB18: 32 | DC18: 32 | DD18: 32 | DE18: 32 | DF18: 32 | DG18: 32 | DH18: 32 | DI18: 32 | DJ18: 32 | DK18: 32 | DL18: 32 | DM18: 32 | DN18: 32 | DO18: 32 | DP18: 32 | DQ18: 32 | DT18: 32 | DU18: 32 | DV18: 32 | DW18: 32 | DX18: 32 | DY18: 32 | DZ18: 32 | EA18: 32 | EB18: 32 | EC18: 32 | ED18: 32 | EE18: 32 | EF18: 32 | EG18: 32 | EH18: 32 | EI18: 32 | EJ18: 32 | EK18: 32 | EL18: 32 | EM18: 32 | EN18: 32 | EO18: 32 | EP18: 16 | EQ18: 16 | ER18: 16 | ES18: 16 | ET18: 16 | FQ18: =SUMIF($AC$11:$FP$11,FQ$12,$AC18:$FP18) -> #VALUE! | FR18: =SUMIF($AC$11:$FP$11,FR$12,$AC18:$FP18) -> #VALUE! | FS18: =SUMIF($AC$11:$FP$11,FS$12,$AC18:$FP18) -> #VALUE! | FT18: =SUMIF($AC$11:$FP$11,FT$12,$AC18:$FP18) -> #VALUE! | FU18: =SUMIF($AC$11:$FP$11,FU$12,$AC18:$FP18) -> #VALUE! | FV18: =SUMIF($AC$11:$FP$11,FV$12,$AC18:$FP18) -> #VALUE! | FW18: =SUMIF($AC$11:$FP$11,FW$12,$AC18:$FP18) -> #VALUE! | FX18: =SUMIF($AC$11:$FP$11,FX$12,$AC18:$FP18) -> #VALUE! | ... GO18: =SUMIF($AC$11:$FP$11,GO$12,$AC18:$FP18) -> #VALUE!
B19: Process | C19: Solution Architecture | D19: Solution Delivery | E19: Solution Lead - offshore | F19: India | G19: Consulting Services | H19: Enterprise Performance | I19: SAP | J19: India | K19: Package and Technology Enablement | L19: Package Functional Transformation | M19: L55 - Manager | N19: =_xlfn.CONCAT(C19,"-",D19) -> Solution Architecture-Solution Delivery | O19: =_xlfn.CONCAT(Y19,"-",Z19,"-",F19,"-",X19) -> Technology-Senior Consultant-India-Consulting | P19: =_xlfn.CONCAT(C19," - ",Y19) -> Solution Architecture - Technology | Q19: =AB19*SUM(AZ19:ET19) -> 277965 | R19: =AB19*SUM(BC19:BN19) -> 31950 | S19: =SUM(GP19:HN19) -> #VALUE! | T19: =SUM(AZ19:EZ19) -> 3915 | U19: =_xlfn.CONCAT(Y19," - ",Z19) -> Technology - Senior Consultant | V19: =VLOOKUP(O19,$B$187:$H$848,4,0) -> 3-5 years | W19: =IF(F19="US", "Onshore",IF(F19="India","Offshore", "Nearshore")) -> Offshore | X19: Consulting | Y19: Technology | Z19: Senior Consultant | AA19: =[1]Resourcing!QD23 -> 53.073913 | AB19: =IFERROR(VLOOKUP(O19,$B$187:$S$848,6,FALSE()),"combination not found") -> 71 | BE19: 45 | BF19: 45 | BG19: 45 | BH19: 45 | BI19: 45 | BJ19: 45 | BK19: 45 | BL19: 45 | BM19: 45 | BN19: 45 | BO19: 45 | BP19: 45 | BQ19: 45 | BT19: 45 | BU19: 45 | BV19: 45 | BW19: 45 | BX19: 45 | BY19: 45 | BZ19: 45 | CA19: 45 | CB19: 45 | CC19: 45 | CD19: 45 | CE19: 45 | CF19: 45 | CG19: 45 | CH19: 45 | CI19: 45 | CJ19: 45 | CK19: 45 | CL19: 45 | CM19: 45 | CN19: 45 | CO19: 45 | CP19: 45 | CQ19: 45 | CR19: 45 | CS19: 45 | CT19: 45 | CU19: 45 | CV19: 45 | CW19: 45 | CX19: 45 | CY19: 45 | CZ19: 45 | DA19: 45 | DB19: 45 | DC19: 45 | DD19: 45 | DE19: 45 | DF19: 45 | DG19: 45 | DH19: 45 | DI19: 45 | DJ19: 45 | DK19: 45 | DL19: 45 | DM19: 45 | DN19: 45 | DO19: 45 | DP19: 45 | DQ19: 45 | DT19: 45 | DU19: 45 | DV19: 45 | DW19: 45 | DX19: 45 | DY19: 45 | DZ19: 45 | EA19: 45 | EB19: 45 | EC19: 45 | ED19: 45 | EE19: 45 | EF19: 45 | EG19: 45 | EH19: 45 | EI19: 45 | EJ19: 45 | EK19: 45 | EL19: 45 | EM19: 45 | EN19: 45 | EO19: 45 | EP19: 45 | EQ19: 45 | FQ19: =SUMIF($AC$11:$FP$11,FQ$12,$AC19:$FP19) -> #VALUE! | FR19: =SUMIF($AC$11:$FP$11,FR$12,$AC19:$FP19) -> #VALUE! | FS19: =SUMIF($AC$11:$FP$11,FS$12,$AC19:$FP19) -> #VALUE! | FT19: =SUMIF($AC$11:$FP$11,FT$12,$AC19:$FP19) -> #VALUE! | FU19: =SUMIF($AC$11:$FP$11,FU$12,$AC19:$FP19) -> #VALUE! | FV19: =SUMIF($AC$11:$FP$11,FV$12,$AC19:$FP19) -> #VALUE! | FW19: =SUMIF($AC$11:$FP$11,FW$12,$AC19:$FP19) -> #VALUE! | FX19: =SUMIF($AC$11:$FP$11,FX$12,$AC19:$FP19) -> #VALUE! | ... GO19: =SUMIF($AC$11:$FP$11,GO$12,$AC19:$FP19) -> #VALUE! | GP19: =SUMIF($AB$8:$FO$8,GP$9,$AB19:$FO19) -> 90 | GQ19: =SUMIF($AB$8:$FO$8,GQ$9,$AB19:$FO19) -> 180 | GR19: =SUMIF($AB$8:$FO$8,GR$9,$AB19:$FO19) -> 180 | GS19: =SUMIF($AB$8:$FO$8,GS$9,$AB19:$FO19) -> 180 | GT19: =SUMIF($AB$8:$FO$8,GT$9,$AB19:$FO19) -> 180 | GU19: =SUMIF($AB$8:$FO$8,GU$9,$AB19:$FO19) -> 180 | GV19: =SUMIF($AB$8:$FO$8,GV$9,$AB19:$FO19) -> 180 | GW19: =SUMIF($AB$8:$FO$8,GW$9,$AB19:$FO19) -> 0 | ... HE19: =SUMIF($AB$8:$FO$8,HE$9,$AB19:$FO19) -> 0 | HF19: =SUM(FQ19:HE19) -> #VALUE! | HG19: =HF19-S45 -> #VALUE!
Q20: =AB20*SUM(AZ20:ET20) -> 0 | R20: =AB20*SUM(BC20:BN20) -> 0 | T20: =SUM(AZ20:EZ20) -> 0 | AA20: =[1]Resourcing!QD24 -> 0 | FQ20: =SUMIF($AC$11:$FP$11,FQ$12,$AC20:$FP20) -> #VALUE! | FR20: =SUMIF($AC$11:$FP$11,FR$12,$AC20:$FP20) -> #VALUE! | FS20: =SUMIF($AC$11:$FP$11,FS$12,$AC20:$FP20) -> #VALUE! | FT20: =SUMIF($AC$11:$FP$11,FT$12,$AC20:$FP20) -> #VALUE! | FU20: =SUMIF($AC$11:$FP$11,FU$12,$AC20:$FP20) -> #VALUE! | FV20: =SUMIF($AC$11:$FP$11,FV$12,$AC20:$FP20) -> #VALUE! | FW20: =SUMIF($AC$11:$FP$11,FW$12,$AC20:$FP20) -> #VALUE! | FX20: =SUMIF($AC$11:$FP$11,FX$12,$AC20:$FP20) -> #VALUE! | ... GO20: =SUMIF($AC$11:$FP$11,GO$12,$AC20:$FP20) -> #VALUE! | GP20: =SUMIF($AB$8:$FO$8,GP$9,$AB20:$FO20) -> 0 | GQ20: =SUMIF($AB$8:$FO$8,GQ$9,$AB20:$FO20) -> 0 | GR20: =SUMIF($AB$8:$FO$8,GR$9,$AB20:$FO20) -> 0 | GS20: =SUMIF($AB$8:$FO$8,GS$9,$AB20:$FO20) -> 0 | GT20: =SUMIF($AB$8:$FO$8,GT$9,$AB20:$FO20) -> 0 | GU20: =SUMIF($AB$8:$FO$8,GU$9,$AB20:$FO20) -> 0 | GV20: =SUMIF($AB$8:$FO$8,GV$9,$AB20:$FO20) -> 0 | GW20: =SUMIF($AB$8:$FO$8,GW$9,$AB20:$FO20) -> 0 | ... HE20: =SUMIF($AB$8:$FO$8,HE$9,$AB20:$FO20) -> 0 | HF20: =SUM(FQ20:HE20) -> #VALUE! | HG20: =HF20-S57 -> #VALUE!
B21: Process | C21: RTR | D21: RTR | E21: RTR Overall Lead | F21: US | G21: Consulting Services | H21: Enterprise Performance | I21: SAP | J21: US | K21: Package and Technology Enablement | L21: Package Functional Transformation | M21: L65 - Senior Manager | N21: =_xlfn.CONCAT(C21,"-",D21) -> RTR-RTR | O21: =_xlfn.CONCAT(Y21,"-",Z21,"-",F21,"-",X21) -> Technology-Senior Manager-US-Consulting | P21: =_xlfn.CONCAT(C21," - ",Y21) -> RTR - Technology | Q21: =AB21*SUM(AZ21:ET21) -> 984960 | R21: =AB21*SUM(BC21:BN21) -> 109440 | S21: =SUM(GP21:HN21) -> 0 | T21: =SUM(AZ21:EZ21) -> 2880 | U21: =_xlfn.CONCAT(Y21," - ",Z21) -> Technology - Senior Manager | V21: =VLOOKUP(O21,$B$187:$H$848,4,0) -> 7-10 years | W21: =IF(F21="US", "Onshore",IF(F21="India","Offshore", "Nearshore")) -> Onshore | X21: Consulting | Y21: Technology | Z21: Senior Manager | AA21: =[1]Resourcing!QD25 -> 380.11732 | AB21: =IFERROR(VLOOKUP(O21,$B$187:$S$848,6,FALSE()),"combination not found") -> 342 | BE21: 32 | BF21: 32 | BG21: 32 | BH21: 32 | BI21: 32 | BJ21: 32 | BK21: 32 | BL21: 32 | BM21: 32 | BN21: 32 | BO21: 32 | BP21: 32 | BQ21: 32 | BT21: 32 | BU21: 32 | BV21: 32 | BW21: 32 | BX21: 32 | BY21: 32 | BZ21: 32 | CA21: 32 | CB21: 32 | CC21: 32 | CD21: 32 | CE21: 32 | CF21: 32 | CG21: 32 | CH21: 32 | CI21: 32 | CJ21: 32 | CK21: 32 | CL21: 32 | CM21: 32 | CN21: 32 | CO21: 32 | CP21: 32 | CQ21: 32 | CR21: 32 | CS21: 32 | CT21: 32 | CU21: 32 | CV21: 32 | CW21: 32 | CX21: 32 | CY21: 32 | CZ21: 32 | DA21: 32 | DB21: 32 | DC21: 32 | DD21: 32 | DE21: 32 | DF21: 32 | DG21: 32 | DH21: 32 | DI21: 32 | DJ21: 32 | DK21: 32 | DL21: 32 | DM21: 32 | DN21: 32 | DO21: 32 | DP21: 32 | DQ21: 32 | DT21: 32 | DU21: 32 | DV21: 32 | DW21: 32 | DX21: 32 | DY21: 32 | DZ21: 32 | EA21: 32 | EB21: 32 | EC21: 32 | ED21: 32 | EE21: 32 | EF21: 32 | EG21: 32 | EH21: 32 | EI21: 32 | EJ21: 32 | EK21: 32 | EL21: 32 | EM21: 32 | EN21: 32 | EO21: 32 | EP21: 32 | EQ21: 32 | ER21: 32 | ES21: 32 | ET21: 32 | FQ21: =SUMIF($AC$11:$FP$11,FQ$12,$AC21:$FP21) -> #VALUE! | FR21: =SUMIF($AC$11:$FP$11,FR$12,$AC21:$FP21) -> #VALUE! | FS21: =SUMIF($AC$11:$FP$11,FS$12,$AC21:$FP21) -> #VALUE! | FT21: =SUMIF($AC$11:$FP$11,FT$12,$AC21:$FP21) -> #VALUE! | FU21: =SUMIF($AC$11:$FP$11,FU$12,$AC21:$FP21) -> #VALUE! | FV21: =SUMIF($AC$11:$FP$11,FV$12,$AC21:$FP21) -> #VALUE! | FW21: =SUMIF($AC$11:$FP$11,FW$12,$AC21:$FP21) -> #VALUE! | FX21: =SUMIF($AC$11:$FP$11,FX$12,$AC21:$FP21) -> #VALUE! | ... GO21: =SUMIF($AC$11:$FP$11,GO$12,$AC21:$FP21) -> #VALUE!
B22: Process | C22: RTR | D22: RTR | E22: RTR CO Lead | F22: US | G22: Consulting Services | H22: Enterprise Performance | I22: SAP | J22: US | K22: Package and Technology Enablement | L22: Package Functional Transformation | M22: L45 - Senior Consultant | N22: =_xlfn.CONCAT(C22,"-",D22) -> RTR-RTR | O22: =_xlfn.CONCAT(Y22,"-",Z22,"-",F22,"-",X22) -> Technology-Senior Consultant-US-Consulting | P22: =_xlfn.CONCAT(C22," - ",Y22) -> RTR - Technology | Q22: =AB22*SUM(AZ22:ET22) -> 854100 | R22: =AB22*SUM(BC22:BN22) -> 0 | S22: =SUM(GP22:HN22) -> 990 | T22: =SUM(AZ22:EZ22) -> 3285 | U22: =_xlfn.CONCAT(Y22," - ",Z22) -> Technology - Senior Consultant | V22: =VLOOKUP(O22,$B$187:$H$848,4,0) -> 3-5 years | W22: =IF(F22="US", "Onshore",IF(F22="India","Offshore", "Nearshore")) -> Onshore | X22: Consulting | Y22: Technology | Z22: Senior Consultant | AA22: =[1]Resourcing!QD26 -> 85.177241 | AB22: =IFERROR(VLOOKUP(O22,$B$187:$S$848,6,FALSE()),"combination not found") -> 260 | BO22: 45 | BP22: 45 | BQ22: 45 | BT22: 45 | BU22: 45 | BV22: 45 | BW22: 45 | BX22: 45 | BY22: 45 | BZ22: 45 | CA22: 45 | CB22: 45 | CC22: 45 | CD22: 45 | CE22: 45 | CF22: 45 | CG22: 45 | CH22: 45 | CI22: 45 | CJ22: 45 | CK22: 45 | CL22: 45 | CM22: 45 | CN22: 45 | CO22: 45 | CP22: 45 | CQ22: 45 | CR22: 45 | CS22: 45 | CT22: 45 | CU22: 45 | CV22: 45 | CW22: 45 | CX22: 45 | CY22: 45 | CZ22: 45 | DA22: 45 | DB22: 45 | DC22: 45 | DD22: 45 | DE22: 45 | DF22: 45 | DG22: 45 | DH22: 45 | DI22: 45 | DJ22: 45 | DK22: 45 | DL22: 45 | DM22: 45 | DN22: 45 | DO22: 45 | DP22: 45 | DQ22: 45 | DT22: 45 | DU22: 45 | DV22: 45 | DW22: 45 | DX22: 45 | DY22: 45 | DZ22: 45 | EA22: 45 | EB22: 45 | EC22: 45 | ED22: 45 | EE22: 45 | EF22: 45 | EG22: 45 | EH22: 45 | EI22: 45 | EJ22: 45 | EK22: 45 | EL22: 45 | EM22: 45 | FQ22: =SUMIF($AC$11:$FP$11,FQ$12,$AC22:$FP22) -> #VALUE! | FR22: =SUMIF($AC$11:$FP$11,FR$12,$AC22:$FP22) -> #VALUE! | FS22: =SUMIF($AC$11:$FP$11,FS$12,$AC22:$FP22) -> #VALUE! | FT22: =SUMIF($AC$11:$FP$11,FT$12,$AC22:$FP22) -> #VALUE! | FU22: =SUMIF($AC$11:$FP$11,FU$12,$AC22:$FP22) -> #VALUE! | FV22: =SUMIF($AC$11:$FP$11,FV$12,$AC22:$FP22) -> #VALUE! | FW22: =SUMIF($AC$11:$FP$11,FW$12,$AC22:$FP22) -> #VALUE! | FX22: =SUMIF($AC$11:$FP$11,FX$12,$AC22:$FP22) -> #VALUE! | ... GO22: =SUMIF($AC$11:$FP$11,GO$12,$AC22:$FP22) -> #VALUE! | GP22: =SUMIF($AB$8:$FO$8,GP$9,$AB22:$FO22) -> 90 | GQ22: =SUMIF($AB$8:$FO$8,GQ$9,$AB22:$FO22) -> 180 | GR22: =SUMIF($AB$8:$FO$8,GR$9,$AB22:$FO22) -> 180 | GS22: =SUMIF($AB$8:$FO$8,GS$9,$AB22:$FO22) -> 180 | GT22: =SUMIF($AB$8:$FO$8,GT$9,$AB22:$FO22) -> 180 | GU22: =SUMIF($AB$8:$FO$8,GU$9,$AB22:$FO22) -> 180 | GV22: =SUMIF($AB$8:$FO$8,GV$9,$AB22:$FO22) -> 0 | GW22: =SUMIF($AB$8:$FO$8,GW$9,$AB22:$FO22) -> 0 | ... HE22: =SUMIF($AB$8:$FO$8,HE$9,$AB22:$FO22) -> 0
